Workbook

Sheet Порядок пайки
A1: № пакета | B1: Метки | C1: Значение | D1: Тип | E1: Кол-во | F1: Цена/шт, ₽ | G1: Стоимость, ₽ | H1: Спаяно
A2: 1. Резисторы и конденсаторы 0805
A3: 1 | B3: C54 | C3: 3.3nF 25V | D3: CAP_0805 | E3: =LEN(B3)-LEN(SUBSTITUTE(B3,",",""))+1 -> 1 | F3: ='Цены и источники'!E8 -> 15 | G3: =IF(F3="","",E3*F3) -> 15
A4: 2 | B4: C50 | C4: 56nF 25V | D4: CAP_0805 | E4: =LEN(B4)-LEN(SUBSTITUTE(B4,",",""))+1 -> 1 | F4: ='Цены и источники'!E9 -> 15 | G4: =IF(F4="","",E4*F4) -> 15
A5: 3 | B5: C34, C35, C36, C38, C40, C43, C53, C57, C62, C63, C65, C66, C69, C70, C94, C97 | C5: 0.1uF 25V | D5: CAP_0805 | E5: =LEN(B5)-LEN(SUBSTITUTE(B5,",",""))+1 -> 16 | F5: ='Цены и источники'!E10 -> 9.26 | G5: =IF(F5="","",E5*F5) -> 148.16
A6: 4 | B6: C39, C44, C46, C58, C64 | C6: 10uF 25V | D6: CAP_0805 | E6: =LEN(B6)-LEN(SUBSTITUTE(B6,",",""))+1 -> 5 | F6: ='Цены и источники'!E11 -> 17.68 | G6: =IF(F6="","",E6*F6) -> 88.4
A7: 5 | B7: R57 | C7: 51 | D7: RES_0805 | E7: =LEN(B7)-LEN(SUBSTITUTE(B7,",",""))+1 -> 1 | F7: ='Цены и источники'!E12 -> 8.42 | G7: =IF(F7="","",E7*F7) -> 8.42
A8: 6 | B8: R48 | C8: 475 | D8: RES_0805 | E8: =LEN(B8)-LEN(SUBSTITUTE(B8,",",""))+1 -> 1 | F8: ='Цены и источники'!E13 -> 8.42 | G8: =IF(F8="","",E8*F8) -> 8.42
A9: 7 | B9: R44 | C9: 1K | D9: RES_0805 | E9: =LEN(B9)-LEN(SUBSTITUTE(B9,",",""))+1 -> 1 | F9: ='Цены и источники'!E14 -> 8.42 | G9: =IF(F9="","",E9*F9) -> 8.42
A10: 8 | B10: R68, R69, R71, R72 | C10: 2.2K | D10: RES_0805 | E10: =LEN(B10)-LEN(SUBSTITUTE(B10,",",""))+1 -> 4 | F10: ='Цены и источники'!E15 -> 8.42 | G10: =IF(F10="","",E10*F10) -> 33.68
A11: 9 | B11: R46, R47, R49, R51, R53, R54, R59 | C11: 10K | D11: RES_0805 | E11: =LEN(B11)-LEN(SUBSTITUTE(B11,",",""))+1 -> 7 | F11: ='Цены и источники'!E16 -> 8.42 | G11: =IF(F11="","",E11*F11) -> 58.94
A12: 10 | B12: R45 | C12: 18K | D12: RES_0805 | E12: =LEN(B12)-LEN(SUBSTITUTE(B12,",",""))+1 -> 1 | F12: ='Цены и источники'!E17 -> 8.42 | G12: =IF(F12="","",E12*F12) -> 8.42
A13: 11 | B13: R60 | C13: 100K | D13: RES_0805 | E13: =LEN(B13)-LEN(SUBSTITUTE(B13,",",""))+1 -> 1 | F13: ='Цены и источники'!E18 -> 8.42 | G13: =IF(F13="","",E13*F13) -> 8.42
A14: 2. Мелкие диоды и транзисторы
A15: 12 | B15: D13, D14 | C15: BAS70W-04 | D15: BAS70W-04 | E15: =LEN(B15)-LEN(SUBSTITUTE(B15,",",""))+1 -> 2 | F15: ='Цены и источники'!E19 -> 29.47 | G15: =IF(F15="","",E15*F15) -> 58.94
A16: 13 | B16: D10, D11, D16, D17 | D16: BAV99 | E16: =LEN(B16)-LEN(SUBSTITUTE(B16,",",""))+1 -> 4 | F16: ='Цены и источники'!E20 -> 17.68 | G16: =IF(F16="","",E16*F16) -> 70.72
A17: 14 | B17: VT1 | C17: FMMT717TA | D17: FMMT717TA | E17: =LEN(B17)-LEN(SUBSTITUTE(B17,",",""))+1 -> 1 | F17: ='Цены и источники'!E21 -> 69.04 | G17: =IF(F17="","",E17*F17) -> 69.04
A18: 3. Резисторы и конденсаторы 1206
A19: 15 | B19: C13, C17 | C19: 0.01uF 25v | D19: CAP_1206 | E19: =LEN(B19)-LEN(SUBSTITUTE(B19,",",""))+1 -> 2 | F19: ='Цены и источники'!E22 -> 15 | G19: =IF(F19="","",E19*F19) -> 30
A20: 16 | B20: C16 | C20: 0.03uF 25v | D20: CAP_1206 | E20: =LEN(B20)-LEN(SUBSTITUTE(B20,",",""))+1 -> 1 | F20: ='Цены и источники'!E23 -> 20 | G20: =IF(F20="","",E20*F20) -> 20
A21: 17 | B21: C9, C12, C14, C15, C18, C19, C20, C21, C22, C23, C25 | C21: 0.1uF 25v | D21: CAP_1206 | E21: =LEN(B21)-LEN(SUBSTITUTE(B21,",",""))+1 -> 11 | F21: ='Цены и источники'!E24 -> 15 | G21: =IF(F21="","",E21*F21) -> 165
A22: 18 | B22: C52 | C22: 47uF 25V | D22: CAP_1206 | E22: =LEN(B22)-LEN(SUBSTITUTE(B22,",",""))+1 -> 1 | F22: ='Цены и источники'!E25 -> 82.51 | G22: =IF(F22="","",E22*F22) -> 82.51
A23: 19 | B23: R4 | C23: 10 | D23: RES1206 | E23: =LEN(B23)-LEN(SUBSTITUTE(B23,",",""))+1 -> 1 | F23: ='Цены и источники'!E26 -> 8.42 | G23: =IF(F23="","",E23*F23) -> 8.42
A24: 20 | B24: R3, R42, R43 | C24: 180 | D24: RES1206 | E24: =LEN(B24)-LEN(SUBSTITUTE(B24,",",""))+1 -> 3 | F24: ='Цены и источники'!E27 -> 8.42 | G24: =IF(F24="","",E24*F24) -> 25.26
A25: 21 | B25: R6, R9, R10, R15, R16, R17, R18, R19, R20, R21, R22, R30, R32, R34, R35 | C25: 1K | D25: RES1206 | E25: =LEN(B25)-LEN(SUBSTITUTE(B25,",",""))+1 -> 15 | F25: ='Цены и источники'!E28 -> 8.42 | G25: =IF(F25="","",E25*F25) -> 126.3
A26: 22 | B26: R24, R25 | C26: 2K | D26: RES1206 | E26: =LEN(B26)-LEN(SUBSTITUTE(B26,",",""))+1 -> 2 | F26: ='Цены и источники'!E29 -> 8.42 | G26: =IF(F26="","",E26*F26) -> 16.84
A27: 23 | B27: R8, R11, R26, R28, R38, R39, R40, R41 | C27: 10K | D27: RES1206 | E27: =LEN(B27)-LEN(SUBSTITUTE(B27,",",""))+1 -> 8 | F27: ='Цены и источники'!E30 -> 8.42 | G27: =IF(F27="","",E27*F27) -> 67.36
A28: 24 | B28: R36 | C28: 14K | D28: RES1206 | E28: =LEN(B28)-LEN(SUBSTITUTE(B28,",",""))+1 -> 1 | F28: ='Цены и источники'!E31 -> 8.42 | G28: =IF(F28="","",E28*F28) -> 8.42
A29: 25 | B29: R13, R27, R29 | C29: 20K | D29: RES1206 | E29: =LEN(B29)-LEN(SUBSTITUTE(B29,",",""))+1 -> 3 | F29: ='Цены и источники'!E32 -> 8.42 | G29: =IF(F29="","",E29*F29) -> 25.26
A30: 26 | B30: R31, R33 | C30: 25K | D30: RES1206 | E30: =LEN(B30)-LEN(SUBSTITUTE(B30,",",""))+1 -> 2 | F30: ='Цены и источники'!E33 -> 8.42 | G30: =IF(F30="","",E30*F30) -> 16.84
... A33: 29 | B33: R14, R37 | C33: 100K | D33: RES1206 | E33: =LEN(B33)-LEN(SUBSTITUTE(B33,",",""))+1 -> 2 | F33: ='Цены и источники'!E36 -> 8.42 | G33: =IF(F33="","",E33*F33) -> 16.84
A34: 4. Конденсаторы 1210
A35: 30 | B35: C4, C6, C8, C11, C24 | C35: 10uF 50v | D35: CAP1210 | E35: =LEN(B35)-LEN(SUBSTITUTE(B35,",",""))+1 -> 5 | F35: ='Цены и источники'!E37 -> 58.1 | G35: =IF(F35="","",E35*F35) -> 290.5
A36: 5. Микросхемы и генератор
A37: 31 | B37: DD4 | C37: 24LC512 | D37: 24LC512 | E37: =LEN(B37)-LEN(SUBSTITUTE(B37,",",""))+1 -> 1 | F37: ='Цены и источники'!E38 -> 154.08 | G37: =IF(F37="","",E37*F37) -> 154.08
A38: 32 | B38: DD3 | C38: 74LVC1G125GV | D38: 74LVC1G125GV | E38: =LEN(B38)-LEN(SUBSTITUTE(B38,",",""))+1 -> 1 | F38: ='Цены и источники'!E39 -> 30 | G38: =IF(F38="","",E38*F38) -> 30
A39: 33 | B39: DA1 | C39: ACS712 | D39: ACS712 | E39: =LEN(B39)-LEN(SUBSTITUTE(B39,",",""))+1 -> 1 | F39: ='Цены и источники'!E40 -> 336.79 | G39: =IF(F39="","",E39*F39) -> 336.79
A40: 34 | B40: DD1 | C40: ADAU1701JSTZ | D40: ADAU1701JSTZ | E40: =LEN(B40)-LEN(SUBSTITUTE(B40,",",""))+1 -> 1 | F40: ='Цены и источники'!E41 -> 1243.6 | G40: =IF(F40="","",E40*F40) -> 1243.6
A41: 35 | B41: DD5 | C41: ADM811R | D41: ADM811R | E41: =LEN(B41)-LEN(SUBSTITUTE(B41,",",""))+1 -> 1 | F41: ='Цены и источники'!E42 -> 178.5 | G41: =IF(F41="","",E41*F41) -> 178.5
A42: 36 | B42: OSC1 | C42: ASFL1-12.288MHZ | D42: ASFL1-12.288MHZ | E42: =LEN(B42)-LEN(SUBSTITUTE(B42,",",""))+1 -> 1 | F42: ='Цены и источники'!E43 -> 184.39 | G42: =IF(F42="","",E42*F42) -> 184.39
...

Sheet Исходные данные
A1: Метка | B1: Значение | C1: Тип
A2: C1 | B2: 1000uF 50v | C2: K50-35
A3: C2 | B3: 1000uF 50v | C3: K50-35
A4: C3 | B4: 1000uF 50v | C4: K50-35
A5: C4 | B5: 10uF 50v | C5: CAP1210
A6: C5 | B6: 680uF 50v | C6: K50-35
A7: C6 | B7: 10uF 50v | C7: CAP1210
A8: C7 | B8: 680uF 50v | C8: K50-35
A9: C8 | B9: 10uF 50v | C9: CAP1210
A10: C9 | B10: 0.1uF 25v | C10: CAP_1206
A11: C10 | B11: 220uF 50v | C11: K50-35
A12: C11 | B12: 10uF 50v | C12: CAP1210
... A59: D9 | B59: SMBJ5A | C59: SMBJ5A
A60: D10 | C60: BAV99
A61: D11 | C61: BAV99
A62: D12 | B62: SMBJ3V3 | C62: SMBJ3V3
A63: D13 | B63: BAS70W-04 | C63: BAS70W-04
A64: D14 | B64: BAS70W-04 | C64: BAS70W-04
A65: D15 | B65: SMBJ5.0 | C65: SMBJ5.0
A66: D16 | C66: BAV99
A67: D17 | C67: BAV99
A68: DA1 | B68: ACS712 | C68: ACS712
A69: DA2 | B69: LM2940 | C69: LM2940
A70: DA3 | C70: TL494
A71: DA4 | C71: OP2177
A72: DA5 | C72: OP2177
A73: DA6 | C73: OP2177
A74: DA7 | C74: OP2177
A75: DA8 | C75: OP2177
A76: DA9 | B76: LDL1117S33R | C76: LDL1117S33R
A77: DD1 | B77: ADAU1701JSTZ | C77: ADAU1701JSTZ
A78: DD2 | B78: ISO1540DR | C78: ISO1540DR
A79: DD3 | B79: 74LVC1G125GV | C79: 74LVC1G125GV
A80: DD4 | B80: 24LC512 | C80: 24LC512
A81: DD5 | B81: ADM811R | C81: ADM811R
A82: J1 | C82: SWD1
A83: J2 | C83: SWD1
A84: OPT1 | B84: HCPL3120 | C84: HCPL3120
A85: OSC1 | B85: ASFL1-12.288MHZ | C85: ASFL1-12.288MHZ
A86: Q1 | B86: STP80PF55 | C86: STP80PF55
...

Sheet Цены и источники
A1: Ориентировочные цены комплектующих
A2: Проверено 20.09.2026. Цены за 1 шт.; без доставки, налогов, пошлин и наценок посредников.
A3: USD → RUB | B3: 84.1975 | C3: Курс ЦБ с 19.09.2026: https://www.cbr.ru/currency_base/daily/
A4: «Каталог» — найденная цена выбранного исполнения. «Оценка» — предположение; «Оценка по серии» — цена похожего номинала.
A5: Подбор исполнения служит только для оценки стоимости; метки, номиналы и типы в спецификации не заменены.
A7: № пакета | B7: Товар для оценки | C7: Цена источника | D7: Валюта | E7: Цена/шт, ₽ | F7: Основание | G7: Пояснение | H7: Источник
A8: 1 | B8: Точный артикул не подобран | C8: 15 | D8: RUB | E8: =ROUND(C8*IF(D8="USD",$B$3,1),2) -> 15 | F8: Оценка | G8: Оценка для 3,3 нФ / 25 В / 0805; диэлектрик и допуск не заданы. | H8: Цена магазина не подтверждена
A9: 2 | B9: Точный артикул не подобран | C9: 15 | D9: RUB | E9: =ROUND(C9*IF(D9="USD",$B$3,1),2) -> 15 | F9: Оценка | G9: Оценка для 56 нФ / 25 В / 0805; диэлектрик и допуск не заданы. | H9: Цена магазина не подтверждена
A10: 3 | B10: CL21B104KACNNNC | C10: 0.11 | D10: USD | E10: =ROUND(C10*IF(D10="USD",$B$3,1),2) -> 9.26 | F10: Каталог | G10: 100 нФ, 25 В, 0805, X7R, ±10%; пример исполнения для оценки. | H10: https://www.digikey.com/en/products/detail/samsung-electro-mechanics/CL21B104KACNNNC/3886757
A11: 4 | B11: CL21A106KAYNNNE | C11: 0.21 | D11: USD | E11: =ROUND(C11*IF(D11="USD",$B$3,1),2) -> 17.68 | F11: Каталог | G11: 10 мкФ, 25 В, 0805, X5R; пример исполнения. Нет в наличии на странице. | H11: https://www.digikey.com/en/products/detail/samsung-electro-mechanics/CL21A106KAYNNNE/3888549
A12: 5 | B12: RC0805FR-071KL (1 кОм) | C12: 0.1 | D12: USD | E12: =ROUND(C12*IF(D12="USD",$B$3,1),2) -> 8.42 | F12: Оценка по серии | G12: Ориентир по резистору 1 кОм серии 0805; цена именно номинала 51 не подтверждена. | H12: https://www.digikey.com/en/products/detail/yageo/RC0805FR-071KL/727444
A13: 6 | B13: RC0805FR-071KL (1 кОм) | C13: 0.1 | D13: USD | E13: =ROUND(C13*IF(D13="USD",$B$3,1),2) -> 8.42 | F13: Оценка по серии | G13: Ориентир по резистору 1 кОм серии 0805; цена именно номинала 475 не подтверждена. | H13: https://www.digikey.com/en/products/detail/yageo/RC0805FR-071KL/727444
A14: 7 | B14: RC0805FR-071KL (1 кОм) | C14: 0.1 | D14: USD | E14: =ROUND(C14*IF(D14="USD",$B$3,1),2) -> 8.42 | F14: Каталог | G14: Цена за 1 шт.; скидки за количество не применены. | H14: https://www.digikey.com/en/products/detail/yageo/RC0805FR-071KL/727444
A15: 8 | B15: RC0805FR-071KL (1 кОм) | C15: 0.1 | D15: USD | E15: =ROUND(C15*IF(D15="USD",$B$3,1),2) -> 8.42 | F15: Оценка по серии | G15: Ориентир по резистору 1 кОм серии 0805; цена именно номинала 2.2K не подтверждена. | H15: https://www.digikey.com/en/products/detail/yageo/RC0805FR-071KL/727444
A16: 9 | B16: RC0805FR-071KL (1 кОм) | C16: 0.1 | D16: USD | E16: =ROUND(C16*IF(D16="USD",$B$3,1),2) -> 8.42 | F16: Оценка по серии | G16: Ориентир по резистору 1 кОм серии 0805; цена именно номинала 10K не подтверждена. | H16: https://www.digikey.com/en/products/detail/yageo/RC0805FR-071KL/727444
A17: 10 | B17: RC0805FR-071KL (1 кОм) | C17: 0.1 | D17: USD | E17: =ROUND(C17*IF(D17="USD",$B$3,1),2) -> 8.42 | F17: Оценка по серии | G17: Ориентир по резистору 1 кОм серии 0805; цена именно номинала 18K не подтверждена. | H17: https://www.digikey.com/en/products/detail/yageo/RC0805FR-071KL/727444
A18: 11 | B18: RC0805FR-071KL (1 кОм) | C18: 0.1 | D18: USD | E18: =ROUND(C18*IF(D18="USD",$B$3,1),2) -> 8.42 | F18: Оценка по серии | G18: Ориентир по резистору 1 кОм серии 0805; цена именно номинала 100K не подтверждена. | H18: https://www.digikey.com/en/products/detail/yageo/RC0805FR-071KL/727444
A19: 12 | B19: BAS70W-04-7-F | C19: 0.35 | D19: USD | E19: =ROUND(C19*IF(D19="USD",$B$3,1),2) -> 29.47 | F19: Каталог | G19: Нет в наличии на странице; цена под заказ. | H19: https://www.digikey.com/en/products/detail/diodes-incorporated/BAS70W-04-7-F/815026
A20: 13 | B20: BAV99, SMC Diode Solutions | C20: 0.21 | D20: USD | E20: =ROUND(C20*IF(D20="USD",$B$3,1),2) -> 17.68 | F20: Каталог | G20: Производитель в исходнике не задан; пример цены BAV99. | H20: https://www.digikey.com/en/products/detail/smc-diode-solutions/BAV99/6022507
A21: 14 | B21: FMMT717TA | C21: 0.82 | D21: USD | E21: =ROUND(C21*IF(D21="USD",$B$3,1),2) -> 69.04 | F21: Каталог | H21: https://www.digikey.com/en/products/detail/diodes-incorporated/FMMT717TA/243276
A22: 15 | B22: Точный артикул не подобран | C22: 15 | D22: RUB | E22: =ROUND(C22*IF(D22="USD",$B$3,1),2) -> 15 | F22: Оценка | G22: Оценка для 0,01 мкФ / 25 В / 1206; диэлектрик и допуск не заданы. | H22: Цена магазина не подтверждена
A23: 16 | B23: Точный артикул не подобран | C23: 20 | D23: RUB | E23: =ROUND(C23*IF(D23="USD",$B$3,1),2) -> 20 | F23: Оценка | G23: Оценка для 0,03 мкФ / 25 В / 1206. Номинал 0,03 сохранён; не заменён на 0,033. | H23: Цена магазина не подтверждена
A24: 17 | B24: Точный артикул не подобран | C24: 15 | D24: RUB | E24: =ROUND(C24*IF(D24="USD",$B$3,1),2) -> 15 | F24: Оценка | G24: Оценка для 0,1 мкФ / 25 В / 1206; диэлектрик и допуск не заданы. | H24: Цена магазина не подтверждена
A25: 18 | B25: C3216X5R1E476M160AC | C25: 0.98 | D25: USD | E25: =ROUND(C25*IF(D25="USD",$B$3,1),2) -> 82.51 | F25: Каталог | G25: 47 мкФ, 25 В, 1206, X5R; пример исполнения. Нет в наличии на странице. | H25: https://www.digikey.com/en/products/detail/tdk/C3216X5R1E476M160AC/2792260
A26: 19 | B26: RC1206FR-071KL (1 кОм) | C26: 0.1 | D26: USD | E26: =ROUND(C26*IF(D26="USD",$B$3,1),2) -> 8.42 | F26: Оценка по серии | G26: Ориентир по резистору 1 кОм серии 1206; цена именно номинала 10 не подтверждена. | H26: https://www.digikey.com/en/products/detail/yageo/RC1206FR-071KL/728387
A27: 20 | B27: RC1206FR-071KL (1 кОм) | C27: 0.1 | D27: USD | E27: =ROUND(C27*IF(D27="USD",$B$3,1),2) -> 8.42 | F27: Оценка по серии | G27: Ориентир по резистору 1 кОм серии 1206; цена именно номинала 180 не подтверждена. | H27: https://www.digikey.com/en/products/detail/yageo/RC1206FR-071KL/728387
A28: 21 | B28: RC1206FR-071KL (1 кОм) | C28: 0.1 | D28: USD | E28: =ROUND(C28*IF(D28="USD",$B$3,1),2) -> 8.42 | F28: Каталог | G28: Цена за 1 шт.; скидки за количество не применены. | H28: https://www.digikey.com/en/products/detail/yageo/RC1206FR-071KL/728387
A29: 22 | B29: RC1206FR-071KL (1 кОм) | C29: 0.1 | D29: USD | E29: =ROUND(C29*IF(D29="USD",$B$3,1),2) -> 8.42 | F29: Оценка по серии | G29: Ориентир по резистору 1 кОм серии 1206; цена именно номинала 2K не подтверждена. | H29: https://www.digikey.com/en/products/detail/yageo/RC1206FR-071KL/728387
A30: 23 | B30: RC1206FR-071KL (1 кОм) | C30: 0.1 | D30: USD | E30: =ROUND(C30*IF(D30="USD",$B$3,1),2) -> 8.42 | F30: Оценка по серии | G30: Ориентир по резистору 1 кОм серии 1206; цена именно номинала 10K не подтверждена. | H30: https://www.digikey.com/en/products/detail/yageo/RC1206FR-071KL/728387
A31: 24 | B31: RC1206FR-071KL (1 кОм) | C31: 0.1 | D31: USD | E31: =ROUND(C31*IF(D31="USD",$B$3,1),2) -> 8.42 | F31: Оценка по серии | G31: Ориентир по резистору 1 кОм серии 1206; цена именно номинала 14K не подтверждена. | H31: https://www.digikey.com/en/products/detail/yageo/RC1206FR-071KL/728387
A32: 25 | B32: RC1206FR-071KL (1 кОм) | C32: 0.1 | D32: USD | E32: =ROUND(C32*IF(D32="USD",$B$3,1),2) -> 8.42 | F32: Оценка по серии | G32: Ориентир по резистору 1 кОм серии 1206; цена именно номинала 20K не подтверждена. | H32: https://www.digikey.com/en/products/detail/yageo/RC1206FR-071KL/728387
A33: 26 | B33: RC1206FR-071KL (1 кОм) | C33: 0.1 | D33: USD | E33: =ROUND(C33*IF(D33="USD",$B$3,1),2) -> 8.42 | F33: Оценка по серии | G33: Ориентир по резистору 1 кОм серии 1206; цена именно номинала 25K не подтверждена. | H33: https://www.digikey.com/en/products/detail/yageo/RC1206FR-071KL/728387
... A40: 33 | B40: ACS712ELCTR-05B-T | C40: 4 | D40: USD | E40: =ROUND(C40*IF(D40="USD",$B$3,1),2) -> 336.79 | F40: Каталог | G40: Для оценки взято исполнение 5 А; в спецификации указан только ACS712. | H40: https://www.digikey.com/en/products/detail/allegro-microsystems/ACS712ELCTR-05B-T/1284593
A41: 34 | B41: ADAU1701JSTZ | C41: 14.77 | D41: USD | E41: =ROUND(C41*IF(D41="USD",$B$3,1),2) -> 1243.6 | F41: Каталог | H41: https://www.digikey.com/en/products/detail/analog-devices-inc/ADAU1701JSTZ/1246074
A42: 35 | B42: ADM811RARTZ-REEL7 | C42: 2.12 | D42: USD | E42: =ROUND(C42*IF(D42="USD",$B$3,1),2) -> 178.5 | F42: Каталог | G42: Для оценки взято исполнение SOT-143-4. | H42: https://www.digikey.com/en/products/detail/analog-devices-inc/ADM811RARTZ-REEL7/1007315
A43: 36 | B43: ASFL1-12.288MHZ-EC-T | C43: 2.19 | D43: USD | E43: =ROUND(C43*IF(D43="USD",$B$3,1),2) -> 184.39 | F43: Каталог | G43: Для оценки взят суффикс EC-T; полный суффикс в исходнике отсутствует. | H43: https://www.digikey.com/en/products/detail/abracon-llc/ASFL1-12-288MHZ-EC-T/687856
A44: 37 | B44: ISO1540DR | C44: 4.68 | D44: USD | E44: =ROUND(C44*IF(D44="USD",$B$3,1),2) -> 394.04 | F44: Каталог | G44: Нет в наличии на странице; цена под заказ. | H44: https://www.digikey.com/en/products/detail/texas-instruments/ISO1540DR/3587222
A45: 38 | B45: LDL1117S33R | C45: 0.41 | D45: USD | E45: =ROUND(C45*IF(D45="USD",$B$3,1),2) -> 34.52 | F45: Каталог | H45: https://www.digikey.com/en/products/detail/stmicroelectronics/LDL1117S33R/7102071
A46: 39 | B46: OP2177ARZ | C46: 6.61 | D46: USD | E46: =ROUND(C46*IF(D46="USD",$B$3,1),2) -> 556.55 | F46: Каталог | G46: Для оценки взят SOIC-8; полный суффикс отсутствует. Нет в наличии на странице. | H46: https://www.digikey.com/en/products/detail/analog-devices-inc/OP2177ARZ/820332
A47: 40 | B47: TL494CDR | C47: 0.45 | D47: USD | E47: =ROUND(C47*IF(D47="USD",$B$3,1),2) -> 37.89 | F47: Каталог | G47: Для оценки взят SOIC-16; корпус в исходнике не указан. | H47: https://www.digikey.com/en/products/detail/texas-instruments/TL494CDR/276936
...
